<mujoco model="RL_BOY">
    <compiler angle="radian" meshdir="meshes/"/>
    <option timestep="0.001" tolerance="1e-10" solver="Newton" jacobian="dense" cone="pyramidal"
            gravity="0 0 -9.81">  <!--integrator="RK4"  iteration="50"-->
        <flag contact="enable" energy="enable"/>
    </option>
    <size njmax="500" nconmax="1000"/>
    <default>
        <light castshadow="false"/>
        <geom rgba="0.784 0.784 0.784 1"/>
        <default class="visual">
            <geom contype="0" conaffinity="0" group="1" type="mesh" euler="1.57 0 0"/>
        </default>
        <default class="collision">
            <geom contype="1" conaffinity="1" friction="1.0 0.3 0.3"
                  margin="0.001" group="0" euler="1.57 0 0"/>
        </default>
        <joint damping="0.1" frictionloss="0.02" armature="0.01"/>
    </default>

    <asset>
        <mesh name="base_link" file="base_link.STL"/>
        <mesh name="left_hip_yaw_link" file="left_hip_yaw_link.STL"/>
        <mesh name="left_hip_roll_link" file="left_hip_roll_link.STL"/>
        <mesh name="left_hip_pitch_link" file="left_hip_pitch_link.STL"/>
        <mesh name="left_knee_pitch_link" file="left_knee_pitch_link.STL"/>
        <mesh name="left_ankle_pitch_link" file="left_ankle_pitch_link.STL"/>
        <mesh name="right_hip_yaw_link" file="right_hip_yaw_link.STL"/>
        <mesh name="right_hip_roll_link" file="right_hip_roll_link.STL"/>
        <mesh name="right_hip_pitch_link" file="right_hip_pitch_link.STL"/>
        <mesh name="right_knee_pitch_link" file="right_knee_pitch_link.STL"/>
        <mesh name="right_ankle_pitch_link" file="right_ankle_pitch_link.STL"/>
        <mesh name="waist_yaw_link" file="waist_yaw_link.STL"/>
        <mesh name="head_yaw_link" file="head_yaw_link.STL"/>
        <mesh name="left_shoulder_pitch_link" file="left_shoulder_pitch_link.STL"/>
        <mesh name="left_shoulder_roll_link" file="left_shoulder_roll_link.STL"/>
        <mesh name="left_shoulder_yaw_link" file="left_shoulder_yaw_link.STL"/>
        <mesh name="left_elbow_pitch_link" file="left_elbow_pitch_link.STL"/>
        <mesh name="right_shoulder_pitch_link" file="right_shoulder_pitch_link.STL"/>
        <mesh name="right_shoulder_roll_link" file="right_shoulder_roll_link.STL"/>
        <mesh name="right_shoulder_yaw_link" file="right_shoulder_yaw_link.STL"/>
        <mesh name="right_elbow_pitch_link" file="right_elbow_pitch_link.STL"/>
    </asset>

    <worldbody>
        <body name="base_link" pos="0.00000000 0.00000000 0.4265" quat="1 0 0 0">
            <joint name="floating_base_joint" type="free" limited="false" actuatorfrclimited="false"/>
            <geom type="mesh" rgba="0.349 0.333 0.345 1" mesh="base_link"/>
            <body name="left_hip_yaw_link" pos="0 0.044471 -0.0372" quat="1.0 0.0 0.0 0.0">
                <joint name="left_hip_yaw_joint" range="-0.62 0.62" axis="0 0 1"/>
                <inertial pos="-0.00294137489640708 -2.54825399199493E-05 -0.0410789597035129" quat="1.0 0.0 0.0 0.0"
                          mass="0.389943638059841" diaginertia="0.0003 0.0002 0.0001"/>
                <geom type="mesh" rgba="1 1 1 1" mesh="left_hip_yaw_link"/>
                <body name="left_hip_roll_link" pos="0.010458 0 -0.043869" quat="1.0 0.0 0.0 0.0">
                    <joint name="left_hip_roll_joint" range="-0.41 0.37" axis="-1 0 0"/>
                    <inertial pos="-0.000428254367153769 0.0256328212746396 -0.00860134346783947" quat="1.0 0.0 0.0 0.0"
                              mass="0.0748963568033087"
                              diaginertia="4.31603214258508e-05 2.12456920352261e-05 3.47985461577559e-05"/>
                    <geom type="mesh" rgba="1 1 1 1" mesh="left_hip_roll_link"/>
                    <body name="left_hip_pitch_link" pos="-0.011958 0.049812 -0.014483" quat="1.0 0.0 0.0 0.0">
                        <joint name="left_hip_pitch_joint" range="-1.2 1.2" axis="0 1 0"/>
                        <inertial pos="0.000928598617549195 0.0180138517526988 -0.0736411932689468"
                                  quat="1.0 0.0 0.0 0.0" mass="1.37410018353659" diaginertia="0.0075 0.0082 0.001"/>
                        <geom type="mesh" rgba="1 1 1 1" mesh="left_hip_pitch_link"/>
                        <body name="left_knee_pitch_link" pos="0 0.0025 -0.14738" quat="1.0 0.0 0.0 0.0">
                            <joint name="left_knee_pitch_joint" range="0 2.2" axis="0 1 0"/>
                            <inertial pos="-6.16798641245309E-06 0.00544332219817939 -0.117248013665112"
                                      quat="1.0 0.0 0.0 0.0" mass="0.505878301704643"
                                      diaginertia="0.0011 0.0012 0.0002"/>
                            <geom type="mesh" rgba="1 1 1 1" mesh="left_knee_pitch_link"/>
                            <body name="left_ankle_pitch_link" pos="0 0.023 -0.14049" quat="1.0 0.0 0.0 0.0">
                                <joint name="left_ankle_pitch_joint" range="-0.9 0.9" axis="0 -1 0"/>
                                <inertial pos="0.0117428949089268 -0.00344235005565224 -0.0255454810959219"
                                          quat="1.0 0.0 0.0 0.0" mass="0.164848246105153"
                                          diaginertia="0.0001 0.0003 0.0003"/>
                                <geom name="left_ankle_pitch_link" type="mesh" rgba="1 1 1 1" mesh="left_ankle_pitch_link"/>
                                <site name="left_foot" pos="0.0 0.0 -0.03" size="0.01" rgba="1 0 0 1"/>
                            </body>
                        </body>
                            <body name="dummy_left_knee_link" pos="-0.1 0.0 -0.2">
                                <site type="sphere" pos="0 0 0" size="0.01" rgba="1 0 0 1"/>
                            </body>
                    </body>
                </body>
            </body>
            <body name="right_hip_yaw_link" pos="0 -0.044471 -0.0377" quat="1.0 0.0 0.0 0.0">
                <joint name="right_hip_yaw_joint" range="-0.62 0.62" axis="0 0 1"/>
                <inertial pos="-0.0029413748964071 -2.55329180031258E-05 -0.0405790096015032" quat="1.0 0.0 0.0 0.0"
                          mass="0.389943638059841" diaginertia="0.0003 0.0002 0.0001"/>
                <geom type="mesh" rgba="1 1 1 1" mesh="right_hip_yaw_link"/>
                <body name="right_hip_roll_link" pos="0.010458 0 -0.043369" quat="1.0 0.0 0.0 0.0">
                    <joint name="right_hip_roll_joint" range="-0.37 0.41" axis="-1 0 0"/>
                    <inertial pos="-0.000417158180163357 -0.0255979663346856 -0.00859270822921364"
                              quat="1.0 0.0 0.0 0.0" mass="0.0747884634401012"
                              diaginertia="4.30774608747953e-05 2.12071220587149e-05 3.47136743221189e-05"/>
                    <geom type="mesh" rgba="1 1 1 1" mesh="right_hip_roll_link"/>
                    <body name="right_hip_pitch_link" pos="-0.011958 -0.05228 -0.014483" quat="1.0 0.0 0.0 0.0">
                        <joint name="right_hip_pitch_joint" range="-1.2 1.2" axis="0 -1 0"/>
                        <inertial pos="0.000929553708730851 -0.0154929447459764 -0.0738650565509665"
                                  quat="1.0 0.0 0.0 0.0" mass="1.37249220922042" diaginertia="0.0075 0.0082 0.001"/>
                        <geom type="mesh" rgba="1 1 1 1" mesh="right_hip_pitch_link"/>
                        <body name="right_knee_pitch_link" pos="0 0 -0.14738" quat="1.0 0.0 0.0 0.0">
                            <joint name="right_knee_pitch_joint" range="-2.2 0" axis="0 -1 0"/>
                            <inertial pos="2.67947782028877E-06 -0.00594332219817919 -0.117347197031427"
                                      quat="1.0 0.0 0.0 0.0" mass="0.505878301704643"
                                      diaginertia="0.0011 0.0012 0.0002"/>
                            <geom type="mesh" rgba="1 1 1 1" mesh="right_knee_pitch_link"/>
                            <body name="right_ankle_pitch_link" pos="0 -0.0235 -0.14063" quat="1.0 0.0 0.0 0.0">
                                <joint name="right_ankle_pitch_joint" range="-0.9 0.9" axis="0 1 0"/>
                                <inertial pos="0.0117473846429926 0.00344235013266297 -0.025408399829584"
                                          quat="1.0 0.0 0.0 0.0" mass="0.164848244951365"
                                          diaginertia="0.0001 0.0003 0.0003"/>
                                <geom name="right_ankle_pitch_link" type="mesh" rgba="1 1 1 1" mesh="right_ankle_pitch_link"/>
                                <site name="right_foot" pos="0.0 0.0 -0.03" size="0.01" rgba="1 0 0 1"/>
                            </body>
                        </body>
                            <body name="dummy_right_knee_link" pos="-0.1 0.0 -0.2">
                                <site type="sphere" pos="0 0 0" size="0.01" rgba="1 0 0 1"/>
                            </body>
                    </body>
                </body>
            </body>
            <body name="waist_yaw_link" pos="0 0 0.0173" quat="1.0 0.0 0.0 0.0">
                <joint name="waist_yaw_joint" range="-0.8 0.8" axis="0 0 -1"/>
                <inertial pos="0.0104405622097244 0.000140950688000123 0.106181059453868" quat="1.0 0.0 0.0 0.0"
                          mass="2.29504940573466" diaginertia="0.0114 0.0096 0.0075"/>
                <geom type="mesh" rgba="0.349 0.333 0.345 0.8" mesh="waist_yaw_link"/>
                <body name="head_yaw_link" pos="0.0043463 -0.00035114 0.206" quat="1.0 0.0 0.0 0.0">
                    <!-- <joint name="head_yaw_joint" range="-1 1" axis="0 0 -1"/> -->
                    <inertial pos="0.00345840204640692 -6.11136761708361E-05 0.081935077450344" quat="1.0 0.0 0.0 0.0"
                              mass="1.44396977917988" diaginertia="0.0071 0.0062 0.0071"/>
                    <geom type="mesh" rgba="0.769 0.278 0.49 1" mesh="head_yaw_link"/>
                </body>
                <body name="left_shoulder_pitch_link" pos="0.0027606 0.11202 0.15563" quat="1.0 0.0 0.0 0.0">
                    <joint name="left_shoulder_pitch" range="-0.7 0.7" axis="0 -1 0"/>
                    <inertial pos="-0.00138930918764134 0.0245992855187893 -0.00013357638537026" quat="1.0 0.0 0.0 0.0"
                              mass="0.0876598395302804"
                              diaginertia="2.83939818173853e-05 2.40871469900306e-05 2.37304171270035e-05"/>
                    <geom type="mesh" rgba="1 1 1 1" mesh="left_shoulder_pitch_link"/>
                    <body name="left_shoulder_roll_link" pos="0.021788 0.029383 -0.00039063" quat="1.0 0.0 0.0 0.0">
                        <joint name="left_shoulder_roll" range="-0.7 1.5" axis="-1 0 0"/>
                        <inertial pos="-0.0161608641591375 0.0408359820782776 0.000472320097605061"
                                  quat="1.0 0.0 0.0 0.0" mass="0.0940869737408553"
                                  diaginertia="2.87077347610669e-05 3.32759281207454e-05 3.32947127192021e-05"/>
                        <geom type="mesh" rgba="1 1 1 1" mesh="left_shoulder_roll_link"/>
                        <body name="left_shoulder_yaw_link" pos="-0.021771 0.036117 0.00039063" quat="1.0 0.0 0.0 0.0">
                            <joint name="left_shoulder_yaw" range="-0.5 0.5" axis="0 1 0"/>
                            <inertial pos="-0.00053766058009061 0.0844666017380195 0.000632474949067069"
                                      quat="1.0 0.0 0.0 0.0" mass="0.339220471930314"
                                      diaginertia="0.000199547927753336 0.000122490771095339 0.000207350026105091"/>
                            <geom type="mesh" rgba="1 1 1 1" mesh="left_shoulder_yaw_link"/>
                            <body name="left_elbow_pitch_link" pos="-0.00051802 0.10252 0.024852" quat="1.0 0.0 0.0 0.0">
                                <joint name="left_elbow_pitch" range="-0 2.1" axis="0 0 -1"/>
                                <inertial pos="-0.000383361130849746 0.0786213187821886 -0.0139073464544782"
                                          quat="1.0 0.0 0.0 0.0" mass="0.189629147108403"
                                          diaginertia="0.000180753463887672 6.63640220181743e-05 0.000189881632772511"/>
                                <geom type="mesh" rgba="1 1 1 1" mesh="left_elbow_pitch_link"/>
                                <body name="left_wrist_link" pos="0 0.15 -0.02" quat="1.0 0.0 0.0 0.0">
                                    <geom size="0.005" pos="0.0 0.0 0.0" rgba="1 0 0 1"/>
                                </body>
                            </body>
                        </body>
                    </body>
                </body>
                <body name="right_shoulder_pitch_link" pos="0.0027776 -0.11178 0.15563" quat="1.0 0.0 0.0 0.0">
                    <joint name="right_shoulder_pitch" range="-0.7 0.7" axis="0 1 0"/>
                    <inertial pos="-0.0013893091876427 -0.0245994613203168 0.000304917764887891" quat="1.0 0.0 0.0 0.0"
                              mass="0.0876598395302806"
                              diaginertia="2.83939818173853e-05 2.40871469900306e-05 2.37304171270035e-05"/>
                    <geom type="mesh" rgba="1 1 1 1" mesh="right_shoulder_pitch_link"/>
                    <body name="right_shoulder_roll_link" pos="0.021788 -0.029383 0.00039063" quat="1.0 0.0 0.0 0.0">
                        <joint name="right_shoulder_roll" range="-1.5 0.7" axis="-1 0 0"/>
                        <inertial pos="-0.0161608626268088 -0.0408359876675656 0.000472722224356903"
                                  quat="1.0 0.0 0.0 0.0" mass="0.0940869500670276"
                                  diaginertia="2.87077222013288e-05 3.32759131836503e-05 3.32947099686555e-05"/>
                        <geom type="mesh" rgba="1 1 1 1" mesh="right_shoulder_roll_link"/>
                        <body name="right_shoulder_yaw_link" pos="-0.021771 -0.043647 0.00039063" quat="1.0 0.0 0.0 0.0">
                            <joint name="right_shoulder_yaw" range="-0.5 0.5" axis="0 -1 0"/>
                            <inertial pos="-0.00051229708703128 -0.076834510118212 0.000628064345700424"
                                      quat="1.0 0.0 0.0 0.0" mass="0.339635114694512"
                                      diaginertia="0.000200950091079501 0.000122828595463614 0.000208799658035569"/>
                            <geom type="mesh" rgba="1 1 1 1" mesh="right_shoulder_yaw_link"/>
                            <body name="right_elbow_pitch_link" pos="-0.00051802 -0.094987 0.024852" quat="1.0 0.0 0.0 0.0">
                                <joint name="right_elbow_pitch" range="0 2.1" axis="0 0 1"/>
                                <inertial pos="0.000107924576638455 -0.0787473068327355 -0.0139184598692405"
                                          quat="1.0 0.0 0.0 0.0" mass="0.190087955334739"
                                          diaginertia="0.00018079927233131 6.63794599130146e-05 0.000189921202487582"/>
                                <geom type="mesh" rgba="1 1 1 1" mesh="right_elbow_pitch_link"/>
                                <body name="right_wrist_link" pos="0 -0.15 -0.02" quat="1.0 0.0 0.0 0.0">
                                    <geom size="0.005" pos="0.0 0.0 0.0" rgba="1 0 0 1"/>
                                </body>
                            </body>
                        </body>
                    </body>
                </body>
            </body>
            <body name="torso_link" pos="0 0 0.15" quat="1 0 0 0">
                <geom size="0.005" pos="0.0 0.0 0.0" rgba="1 0 0 1"/>
            </body>
            <site name="base_link_site" pos="0 0 0" quat="1 0 0 0"/>
            <camera name="front_camera" mode="track" fovy="90.0"
                    quat="4.329780281177467e-17 4.329780281177466e-17 0.7071067811865475 0.7071067811865476"
                    pos="0.0 2.0 0.5"/>
            <camera name="side_camera" mode="track" fovy="90.0" quat="-0.5 -0.4999999999999999 0.5 0.5000000000000001"
                    pos="-2.0 0.0 0.5"/>
        </body>
    </worldbody>

    <actuator>
        <motor name="left_hip_yaw_joint_ctrl" joint="left_hip_yaw_joint"/>
        <motor name="left_hip_roll_joint_ctrl" joint="left_hip_roll_joint"/>
        <motor name="left_hip_pitch_joint_ctrl" joint="left_hip_pitch_joint"/>
        <motor name="left_knee_pitch_joint_ctrl" joint="left_knee_pitch_joint"/>
        <motor name="left_ankle_pitch_joint_ctrl" joint="left_ankle_pitch_joint"/>
        <motor name="right_hip_yaw_joint_ctrl" joint="right_hip_yaw_joint"/>
        <motor name="right_hip_roll_joint_ctrl" joint="right_hip_roll_joint"/>
        <motor name="right_hip_pitch_joint_ctrl" joint="right_hip_pitch_joint"/>
        <motor name="right_knee_pitch_joint_ctrl" joint="right_knee_pitch_joint"/>
        <motor name="right_ankle_pitch_joint_ctrl" joint="right_ankle_pitch_joint"/>
        <motor name="waist_yaw_joint_ctrl" joint="waist_yaw_joint"/>
        <!-- <motor name="head_yaw_joint_ctrl" joint="head_yaw_joint"/> -->
        <motor name="left_shoulder_pitch_ctrl" joint="left_shoulder_pitch"/>
        <motor name="left_shoulder_roll_ctrl" joint="left_shoulder_roll"/>
        <motor name="left_shoulder_yaw_ctrl" joint="left_shoulder_yaw"/>
        <motor name="left_elbow_pitch_ctrl" joint="left_elbow_pitch"/>
        <motor name="right_shoulder_pitch_ctrl" joint="right_shoulder_pitch"/>
        <motor name="right_shoulder_roll_ctrl" joint="right_shoulder_roll"/>
        <motor name="right_shoulder_yaw_ctrl" joint="right_shoulder_yaw"/>
        <motor name="right_elbow_pitch_ctrl" joint="right_elbow_pitch"/>
    </actuator>

    <contact>base_link_site_angvel
        <exclude body1="base_link" body2="left_hip_yaw_link"/>
        <exclude body1="left_hip_yaw_link" body2="left_hip_roll_link"/>
        <exclude body1="left_hip_roll_link" body2="left_hip_pitch_link"/>
        <exclude body1="left_hip_pitch_link" body2="left_knee_pitch_link"/>
        <exclude body1="left_knee_pitch_link" body2="left_ankle_pitch_link"/>
        <exclude body1="base_link" body2="right_hip_yaw_link"/>
        <exclude body1="right_hip_yaw_link" body2="right_hip_roll_link"/>
        <exclude body1="right_hip_roll_link" body2="right_hip_pitch_link"/>
        <exclude body1="right_hip_pitch_link" body2="right_knee_pitch_link"/>
        <exclude body1="right_knee_pitch_link" body2="right_ankle_pitch_link"/>
        <exclude body1="base_link" body2="waist_yaw_link"/>
        <exclude body1="waist_yaw_link" body2="head_yaw_link"/>
        <exclude body1="waist_yaw_link" body2="left_shoulder_pitch_link"/>
        <exclude body1="left_shoulder_pitch_link" body2="left_shoulder_roll_link"/>
        <exclude body1="left_shoulder_roll_link" body2="left_shoulder_yaw_link"/>
        <exclude body1="left_shoulder_yaw_link" body2="left_elbow_pitch_link"/>
        <exclude body1="waist_yaw_link" body2="right_shoulder_pitch_link"/>
        <exclude body1="right_shoulder_pitch_link" body2="right_shoulder_roll_link"/>
        <exclude body1="right_shoulder_roll_link" body2="right_shoulder_yaw_link"/>
        <exclude body1="right_shoulder_yaw_link" body2="right_elbow_pitch_link"/>
    </contact>

    <sensor>
        <framepos name="base_link_site_pos" objtype="site" objname="base_link_site"/>
        <framequat name="base_link_site_quat" objtype="site" objname="base_link_site"/>
        <framelinvel name="base_link_site_linvel" objtype="site" objname="base_link_site"/>
        <frameangvel name="base_link_site_angvel" objtype="site" objname="base_link_site"/>
        <velocimeter name="base_link_site_vel" site="base_link_site"/>
        <gyro name="imu_ang_vel" site="base_link_site"/>
        <velocimeter name="imu_lin_vel" site="base_link_site"/>
        <subtreeangmom name="root_angmom" body="base_link"/>
    </sensor>
    <statistic center="1.0 0.7 1.0" extent="0.8"/>
    <visual>
        <headlight diffuse="0.6 0.6 0.6" ambient="0.1 0.1 0.1" specular="0.9 0.9 0.9"/>
        <rgba haze="0.15 0.25 0.35 1"/>
        <global azimuth="-140" elevation="-20"/>
    </visual>
    <asset>
        <texture type="skybox" builtin="flat" rgb1="0 0 0" rgb2="0 0 0" width="512" height="3072"/>
        <texture type="2d" name="groundplane" builtin="checker" mark="edge" rgb1="0.2 0.3 0.4" rgb2="0.1 0.2 0.3"
                 markrgb="0.8 0.8 0.8" width="300" height="300"/>
        <material name="groundplane" texture="groundplane" texuniform="true" texrepeat="5 5" reflectance="0.2"/>
    </asset>
    <worldbody>
        <light pos="1 0 3.5" dir="0 0 -1" directional="true"/>
        <geom name="floor" size="0 0 0.05" type="plane" material="groundplane"/>
    </worldbody>
</mujoco>